2025-04-25 15:42:59,730 - exception_logger - ERROR - An exception occurred
Traceback (most recent call last):
  File "C:\Users\cheta\AppData\Local\Temp\ipykernel_15120\3259282278.py", line 12, in log_exception
    1 / 0
    ~~^~~
ZeroDivisionError: division by zero
